Workbook

Sheet Inputs
B1: ARPU MONTHLY | F1: LTV CAC BY CHANNEL | M1: ASSUMPTIONS
A2: month | B2: total_revenue | C2: active_users | D2: arpu | F2: channel | G2: users_acquired | H2: avg_ltv | I2: total_spend | J2: cac | K2: ltv_to_cac_ratio | O2: Base | P2: Bull | Q2: Bear
A3: 2023-01 | B3: 1813.26 | C3: 752 | D3: 2.41 | F3: Organic | G3: 7534 | H3: 44.79 | I3: 202410 | J3: 7 | K3: 1.72 | M3: Monthly signup growth % | O3: 0.04 | P3: 0.06 | Q3: 0.02
A4: 2023-02 | B4: 4453.8 | C4: 1472 | D4: 3.03 | F4: Referral | G4: 4488 | H4: 44.56 | I4: 412770 | J4: 16 | K4: 0.49 | M4: Monthly churn % | O4: 0.03 | P4: 0.02 | Q4: 0.06
A5: 2023-03 | B5: 7876.8 | C5: 2215 | D5: 3.56 | F5: Paid Social | G5: 8957 | H5: 44.67 | I5: 1048900 | J5: 27 | K5: 0.38 | M5: Monthly ARPU growth % | O5: 0.02 | P5: 0.03 | Q5: 0.005
A6: 2023-04 | B6: 10263.72 | C6: 2925 | D6: 3.51 | F6: Paid Search | G6: 6042 | H6: 45.19 | I6: 1471295 | J6: 45 | K6: 0.19 | M6: Annual CAC inflation % | O6: 0.08 | P6: 0.04 | Q6: 0.15
A7: 2023-05 | B7: 13550.26 | C7: 3590 | D7: 3.77 | F7: Influencer | G7: 2979 | H7: 45.01 | I7: 1642600 | J7: 70 | K7: 0.08 | M7: Operating cost % | O7: 0.6 | P7: 0.5 | Q7: 0.7
A8: 2023-06 | B8: 15145.44 | C8: 4238 | D8: 3.57 | I8: Avg. | J8: =SUM(J3:J7)/5 -> 33
A9: 2023-07 | B9: 18543.95 | C9: 4936 | D9: 3.76
A10: 2023-08 | B10: 21084.51 | C10: 5548 | D10: 3.8 | N10: STARTING VALUES
A11: 2023-09 | B11: 22674.1 | C11: 6068 | D11: 3.74 | N11: Starting MAU | O11: 14141
A12: 2023-10 | B12: 25698.18 | C12: 6698 | D12: 3.84 | N12: Starting ARPU | O12: 3.96
A13: 2023-11 | B13: 26641.39 | C13: 7187 | D13: 3.71 | N13: Starting monthly signups | O13: 900
A14: 2023-12 | B14: 30059.64 | C14: 7643 | D14: 3.93 | N14: Starting blended CAC | O14: 33
A15: 2024-01 | B15: 31351.43 | C15: 8100 | D15: 3.87
A16: 2024-02 | B16: 30955.75 | C16: 8485 | D16: 3.65
A17: 2024-03 | B17: 34617.77 | C17: 8870 | D17: 3.9
A18: 2024-04 | B18: 34751.37 | C18: 9214 | D18: 3.77
A19: 2024-05 | B19: 37742.62 | C19: 9587 | D19: 3.94
A20: 2024-06 | B20: 38171.13 | C20: 9907 | D20: 3.85
A21: 2024-07 | B21: 40344.34 | C21: 10302 | D21: 3.92
A22: 2024-08 | B22: 41554.63 | C22: 10614 | D22: 3.92
A23: 2024-09 | B23: 41859.6 | C23: 10937 | D23: 3.83
A24: 2024-10 | B24: 44375.06 | C24: 11269 | D24: 3.94
A25: 2024-11 | B25: 43474.2 | C25: 11502 | D25: 3.78
A26: 2024-12 | B26: 45972.76 | C26: 11722 | D26: 3.92
... A38: 2025-12 | B38: 55962.75 | C38: 14141 | D38: 3.96
A45: LTV BY CHANNEL | F45: COHORT RETENTION
A46: channel | B46: users | C46: avg_ltv | D46: total_revenue
A47: Paid Search | B47: 6042 | C47: 42.8 | D47: 258573.47 | F47: cohort_month | G47: months_since_signup | H47: active_users | I47: cohort_users | J47: retention_pct
A48: Influencer | B48: 2979 | C48: 42.61 | D48: 126935.75 | F48: 2023-01 | G48: 0 | H48: 752 | I48: 873 | J48: 86.1
A49: Organic | B49: 7534 | C49: 42.46 | D49: 319883.44 | F49: 2023-01 | G49: 1 | H49: 822 | I49: 873 | J49: 94.2
A50: Referral | B50: 4488 | C50: 42.43 | D50: 190420.1 | F50: 2023-01 | G50: 2 | H50: 782 | I50: 873 | J50: 89.6
A51: Paid Social | B51: 8957 | C51: 42.39 | D51: 379646.59 | F51: 2023-01 | G51: 3 | H51: 744 | I51: 873 | J51: 85.2
F52: 2023-01 | G52: 4 | H52: 714 | I52: 873 | J52: 81.8
F53: 2023-01 | G53: 5 | H53: 682 | I53: 873 | J53: 78.1
F54: 2023-01 | G54: 6 | H54: 642 | I54: 873 | J54: 73.5
F55: 2023-01 | G55: 7 | H55: 614 | I55: 873 | J55: 70.3
F56: 2023-01 | G56: 8 | H56: 582 | I56: 873 | J56: 66.7
F57: 2023-01 | G57: 9 | H57: 557 | I57: 873 | J57: 63.8
...

Sheet Drivers
A1: DRIVERS
A3: Starting MAU | B3: =Inputs!O11 -> 14141
A4: Starting ARPU | B4: =Inputs!O12 -> 3.96
A5: Starting monthly signups | B5: =Inputs!O13 -> 900
A6: Starting blended CAC | B6: =Inputs!O14 -> 33
A8: Active scenario | B8: Base
A10: Selected monthly signup growth % | B10: =INDEX(Inputs!O3:Q3, MATCH(B8, Inputs!O2:Q2, 0)) -> 0.04
A11: Selected monthly churn % | B11: =INDEX(Inputs!O4:Q4, MATCH(B$8, Inputs!O$2:Q$2, 0)) -> 0.03
A12: Selected monthly ARPU growth % | B12: =INDEX(Inputs!O5:Q5, MATCH(B$8, Inputs!O$2:Q$2, 0)) -> 0.02
A13: Selected annual CAC inflation % | B13: =INDEX(Inputs!O6:Q6, MATCH(B$8, Inputs!O$2:Q$2, 0)) -> 0.08
A14: Selected operating cost % | B14: =INDEX(Inputs!O7:Q7, MATCH(B$8, Inputs!O$2:Q$2, 0)) -> 0.6

Sheet Forecast
A1: FORECAST (£)
B3: 46023 | C3: 46054 | D3: 46082 | E3: 46113 | F3: 46143 | G3: 46174 | H3: 46204 | I3: 46235 | J3: 46266 | K3: 46296 | L3: 46327 | M3: 46357 | N3: 46388 | O3: 46419 | P3: 46447 | Q3: 46478 | R3: 46508 | S3: 46539 | T3: 46569 | U3: 46600 | V3: 46631 | W3: 46661 | X3: 46692 | Y3: 46722 | Z3: 46753 | AA3: 46784 | AB3: 46813 | AC3: 46844 | AD3: 46874 | AE3: 46905 | AF3: 46935 | AG3: 46966 | AH3: 46997 | AI3: 47027 | AJ3: 47058 | AK3: 47088
A5: New signups | B5: =Drivers!B5 -> 900 | C5: =B5*(1+Drivers!$B$10) -> 936 | D5: =C5*(1+Drivers!$B$10) -> 973.44 | E5: =D5*(1+Drivers!$B$10) -> 1012.3776 | F5: =E5*(1+Drivers!$B$10) -> 1052.8727 | G5: =F5*(1+Drivers!$B$10) -> 1094.9876 | H5: =G5*(1+Drivers!$B$10) -> 1138.7871 | I5: =H5*(1+Drivers!$B$10) -> 1184.3386 | J5: =I5*(1+Drivers!$B$10) -> 1231.7121 | ... AK5: =AJ5*(1+Drivers!$B$10) -> 3551.4801
A6: CAC per signup (£) | B6: =Drivers!B6 -> 33 | C6: =B6*(1+Drivers!$B$13/12) -> 33.22 | D6: =C6*(1+Drivers!$B$13/12) -> 33.441467 | E6: =D6*(1+Drivers!$B$13/12) -> 33.66441 | F6: =E6*(1+Drivers!$B$13/12) -> 33.888839 | G6: =F6*(1+Drivers!$B$13/12) -> 34.114765 | H6: =G6*(1+Drivers!$B$13/12) -> 34.342197 | I6: =H6*(1+Drivers!$B$13/12) -> 34.571145 | J6: =I6*(1+Drivers!$B$13/12) -> 34.801619 | ... AK6: =AJ6*(1+Drivers!$B$13/12) -> 41.640221
A7: Marketing spend (£) | B7: =B5*B6 -> 29700 | C7: =C5*C6 -> 31093.92 | D7: =D5*D6 -> 32553.261 | E7: =E5*E6 -> 34081.094 | F7: =F5*F6 -> 35680.634 | G7: =G5*G6 -> 37355.245 | H7: =H5*H6 -> 39108.451 | I7: =I5*I6 -> 40943.941 | ... AK7: =AK5*AK6 -> 147884.42
A9: MAU | B9: =Drivers!B3*(1-Drivers!B11)+B5 -> 14616.77 | C9: =B9*(1-Drivers!$B$11)+C5 -> 15114.267 | D9: =C9*(1-Drivers!$B$11)+D5 -> 15634.279 | E9: =D9*(1-Drivers!$B$11)+E5 -> 16177.628 | F9: =E9*(1-Drivers!$B$11)+F5 -> 16745.172 | G9: =F9*(1-Drivers!$B$11)+G5 -> 17337.804 | H9: =G9*(1-Drivers!$B$11)+H5 -> 17956.457 | I9: =H9*(1-Drivers!$B$11)+I5 -> 18602.102 | J9: =I9*(1-Drivers!$B$11)+J5 -> 19275.751 | ... AK9: =AJ9*(1-Drivers!$B$11)+AK5 -> 53193.691
A10: ARPU (£) | B10: =Drivers!B4 -> 3.96 | C10: =B10*(1+Drivers!$B$12) -> 4.0392 | D10: =C10*(1+Drivers!$B$12) -> 4.119984 | E10: =D10*(1+Drivers!$B$12) -> 4.2023837 | F10: =E10*(1+Drivers!$B$12) -> 4.2864314 | G10: =F10*(1+Drivers!$B$12) -> 4.37216 | H10: =G10*(1+Drivers!$B$12) -> 4.4596032 | I10: =H10*(1+Drivers!$B$12) -> 4.5487952 | J10: =I10*(1+Drivers!$B$12) -> 4.6397711 | ... AK10: =AJ10*(1+Drivers!$B$12) -> 7.9195626
A11: Revenue (£) | B11: =B9*B10 -> 57882.409 | C11: =C9*C10 -> 61049.547 | D11: =D9*D10 -> 64412.979 | E11: =E9*E10 -> 67984.6 | F11: =F9*F10 -> 71777.03 | G11: =G9*G10 -> 75803.655 | H11: =H9*H10 -> 80078.675 | I11: =I9*I10 -> 84617.154 | ... AK11: =AK9*AK10 -> 421270.77
A13: Operating costs (£) | B13: =B11*Drivers!B14 -> 34729.446 | C13: =C11*Drivers!$B$14 -> 36629.728 | D13: =D11*Drivers!$B$14 -> 38647.787 | E13: =E11*Drivers!$B$14 -> 40790.76 | F13: =F11*Drivers!$B$14 -> 43066.218 | G13: =G11*Drivers!$B$14 -> 45482.193 | H13: =H11*Drivers!$B$14 -> 48047.205 | I13: =I11*Drivers!$B$14 -> 50770.293 | J13: =J11*Drivers!$B$14 -> 53661.045 | ... AK13: =AK11*Drivers!$B$14 -> 252762.46
A14: Total costs (£) | B14: =B7+B13 -> 64429.446 | C14: =C7+C13 -> 67723.648 | D14: =D7+D13 -> 71201.049 | E14: =E7+E13 -> 74871.855 | F14: =F7+F13 -> 78746.852 | G14: =G7+G13 -> 82837.438 | H14: =H7+H13 -> 87155.656 | I14: =I7+I13 -> 91714.234 | ... AK14: =AK7+AK13 -> 400646.88
A15: EBITDA (£) | B15: =B11-B14 -> -6547.0363 | C15: =C11-C14 -> -6674.1013 | D15: =D11-D14 -> -6788.0698 | E15: =E11-E14 -> -6887.2542 | F15: =F11-F14 -> -6969.8216 | G15: =G11-G14 -> -7033.7829 | H15: =H11-H14 -> -7076.9811 | I15: =I11-I14 -> -7097.0791 | ... AK15: =AK11-AK14 -> 20623.89
A16: EBITDA margin | B16: =B15/B11 -> -0.11310926 | C16: =C15/C11 -> -0.1093227 | D16: =D15/D11 -> -0.10538357 | E16: =E15/E11 -> -0.10130609 | F16: =F15/F11 -> -0.09710379 | G16: =G15/G11 -> -0.092789496 | H16: =H15/H11 -> -0.088375353 | I16: =I15/I11 -> -0.083872817 | ... AK16: =AK15/AK11 -> 0.048956376

Sheet Scenarios
A1: Scenario Summary
A3: Metric | B3: Base | C3: Bull | D3: Bear
A4: Cumulative 3-yr revenue (£) | B4: 6568143.9 | C4: 12110396 | D4: 2778451.6
A5: Final month revenue (£) | B5: 421270.77 | C5: 1036886 | D5: 109679.13
A6: Cumulative 3-yr EBITDA (£) | B6: -38760.751 | C6: 2229335.8 | D6: -1152754.4
A7: Final month EBITDA (£) | B7: 20623.89 | C7: 261967.93 | D7: -58842.566
A8: Final month MAU | B8: 53193.691 | C8: 93053.554 | D8: 23260.371
A9: Final EBITDA margin | B9: 0.048956376 | C9: 0.25264873 | D9: -0.5364974
A10: Months to positive EBITDA | B10: 26 | C10: 3 | D10: Never
